Workbook

Sheet Dados
A1: title | B1: totalScore | C1: reviewsCount | D1: street | E1: city | F1: state | G1: countryCode | H1: website | I1: phone | J1: categoryName | K1: url | L1: has_website | M1: has_website_boxplot | N1: reviewsCount_boxplot
A2: – R. Riachuelo | B2: 0 | C2: 0 | D2: R. Riachuelo, 124 | E2: Rio de Janeiro | F2: Rio de Janeiro | G2: BR | J2: Hotel | K2: https://www.google.com/maps/search/?api=1&query=%E2%80%93%20R.%20Riachuelo&query_place_id=ChIJx3tYmNh_mQARim_DQCoZnBs | L2: SEM | M2: SEM | N2: 0
A3: 37 hostel | B3: 0 | C3: 0 | D3: R. do Morro, 37 | E3: Ipubi | F3: Pernambuco | G3: BR | H3: https://www.facebook.com/37hostel/ | I3: +55 84 99221-5964 | J3: Motel | K3: https://www.google.com/maps/search/?api=1&query=37%20hostel&query_place_id=ChIJExHL9OaPsgcR2uJEQuUkNHg | L3: COM | M3: SIM | N3: 0
A4: 44 Residence | B4: 0 | C4: 0 | D4: R. Ó de Almeida, 545 | E4: Belém | F4: Pará | G4: BR | H4: https://44residence.com/ | J4: Hotel | K4: https://www.google.com/maps/search/?api=1&query=44%20Residence&query_place_id=ChIJce4K7ROPpJIR0if_T7CGzp4 | L4: COM | M4: COM | N4: 0
A5: A Silva da Costa | B5: 0 | C5: 0 | D5: R. Europa | E5: São Luís | F5: Maranhão | G5: BR | J5: Hotel | K5: https://www.google.com/maps/search/?api=1&query=A%20Silva%20da%20Costa&query_place_id=ChIJ8ebmFwCT9gcRbHBqzN0ewJ4 | L5: SEM | M5: SEM | N5: 0
A6: Aa | B6: 0 | C6: 0 | D6: Rua Dallas, A15 | E6: Manaus | F6: Amazonas | G6: BR | J6: Albergue | K6: https://www.google.com/maps/search/?api=1&query=Aa&query_place_id=ChIJQcBWYcobbJIR40CsDmThE2s | L6: SEM | M6: SEM | N6: 0
A7: Abrigo Caramelos do Vale | B7: 0 | C7: 0 | D7: Av. Edgar Píres de Castro, 3899 | E7: Porto Alegre | F7: Rio Grande do Sul | G7: BR | J7: Albergue | K7: https://www.google.com/maps/search/?api=1&query=Abrigo%20Caramelos%20do%20Vale&query_place_id=ChIJ1foMZQCbGZUR2U3DRUuXKuQ | L7: SEM | M7: SEM | N7: 0
A8: Acai Motel | B8: 0 | C8: 0 | D8: GO-320, km 04 | E8: Paraúna | F8: Goiás | G8: BR | I8: +55 64 99319-1429 | J8: Motel | K8: https://www.google.com/maps/search/?api=1&query=Acai%20Motel&query_place_id=ChIJPxAmRT_vYJMRwGU35sPIqls | L8: SEM | M8: SEM | N8: 0
A9: Açai Palace Hotel | B9: 0 | C9: 0 | D9: Av. Antônio Coelho de Carvalho, 1399 | E9: Macapá | F9: Amapá | G9: BR | I9: +55 96 3223-4899 | J9: Hotel | K9: https://www.google.com/maps/search/?api=1&query=A%C3%A7ai%20Palace%20Hotel&query_place_id=ChIJD9z8qw7hYY0ReGZVhb7xNnU | L9: SEM | M9: SEM | N9: 0
A10: Adriane | B10: 0 | C10: 0 | D10: R. Gomes Jardim, 201 | E10: Porto Alegre | F10: Rio Grande do Sul | G10: BR | J10: Hotel | K10: https://www.google.com/maps/search/?api=1&query=Adriane&query_place_id=ChIJAeCJYTN5GZURBQNJ-f48l6Q | L10: SEM | M10: SEM | N10: 0
A11: Airbnb do Luís | B11: 0 | C11: 0 | D11: R. Dois | E11: São Luís | F11: Maranhão | G11: BR | I11: +55 98 98831-2774 | J11: Apart hotel | K11: https://www.google.com/maps/search/?api=1&query=Airbnb%20do%20Lu%C3%ADs&query_place_id=ChIJRX4fCaeR9gcRGaYodcLyUW4 | L11: SEM | M11: SEM | N11: 0
A12: alameda das flavias | B12: 0 | C12: 0 | D12: Av. dos Xavantes, 770 | E12: Macapá | F12: Amapá | G12: BR | J12: Hotel | K12: https://www.google.com/maps/search/?api=1&query=alameda%20das%20flavias&query_place_id=ChIJ00WCSQDhYY0R9vBSbogjcaQ | L12: SEM | M12: SEM | N12: 0
A13: Albergue | B13: 0 | C13: 0 | D13: Av. Sete de Setembro | E13: Petrolina | F13: Pernambuco | G13: BR | J13: Albergue | K13: https://www.google.com/maps/search/?api=1&query=Albergue&query_place_id=ChIJDZ2cfQBxcwcRCG9nJACWOUI | L13: SEM | M13: SEM | N13: 0
A14: Albergue | B14: 0 | C14: 0 | D14: R. das Caravelas, 612 | E14: São Luís | F14: Maranhão | G14: BR | J14: Apartamento | K14: https://www.google.com/maps/search/?api=1&query=Albergue&query_place_id=ChIJ3QgtEayb9gcRIXuIKJefPlU | L14: SEM | M14: SEM | N14: 0
A15: albergue bisca | B15: 0 | C15: 0 | D15: R. Adolfo Muhlman, 84 | E15: Pinhais | F15: Paraná | G15: BR | J15: Albergue | K15: https://www.google.com/maps/search/?api=1&query=albergue%20bisca&query_place_id=ChIJXWdmBADv3JQRednpwPsm2sA | L15: SEM | M15: SEM | N15: 0
A16: Albergue Gravatá | B16: 0 | C16: 0 | D16: Av. Governador Agamenon Magalhães, 317 | E16: Gravatá | F16: Pernambuco | G16: BR | J16: Albergue | K16: https://www.google.com/maps/search/?api=1&query=Albergue%20Gravat%C3%A1&query_place_id=ChIJOR7tRihIqgcR6pcBdYpG8gw | L16: SEM | M16: SEM | N16: 0
A17: Aldeia Multiétinica do Tio Marquinho | B17: 0 | C17: 0 | D17: Tv. Humaitá, 3298 | E17: Belém | F17: Pará | G17: BR | I17: +55 91 98523-8072 | J17: Hospedagem | K17: https://www.google.com/maps/search/?api=1&query=Aldeia%20Multi%C3%A9tinica%20do%20Tio%20Marquinho&query_place_id=ChIJMbvEWzyNpJIRqquOTubrgPU | L17: SEM | M17: SEM | N17: 0
A18: Alimentos | B18: 0 | C18: 0 | D18: R. Santos Dumont, 15 | E18: Crato | F18: Ceará | G18: BR | I18: +55 88 99627-2049 | J18: Albergue | K18: https://www.google.com/maps/search/?api=1&query=Alimentos&query_place_id=ChIJLbp6l2SEoQcR5OK3S9-3PJ4 | L18: SEM | M18: SEM | N18: 0
A19: Alojamento São Francisco | B19: 0 | C19: 0 | D19: Av. João Basílio Tavares, 335 | E19: Mazagão | F19: Amapá | G19: BR | J19: Hotel | K19: https://www.google.com/maps/search/?api=1&query=Alojamento%20S%C3%A3o%20Francisco&query_place_id=ChIJ35Edz9wHnpIRCkmhJJmTxfU | L19: SEM | M19: SEM | N19: 0
A20: Alu Flat lounge | B20: 0 | C20: 0 | D20: R. Fernando Cutrim, s/n | E20: São Luís | F20: Maranhão | G20: BR | I20: +55 98 98519-4215 | J20: Hotel | K20: https://www.google.com/maps/search/?api=1&query=Alu%20Flat%20lounge&query_place_id=ChIJMavuXvuN9gcRMPCr892piF4 | L20: SEM | M20: SEM | N20: 0
A21: ALU HOTEL | B21: 0 | C21: 0 | D21: R. das Paparaubas, 03 - QD 11 | E21: São Luís | F21: Maranhão | G21: BR | I21: +55 98 98519-4215 | J21: Hotel | K21: https://www.google.com/maps/search/?api=1&query=ALU%20HOTEL&query_place_id=ChIJlSlSmfOP9gcR0uNcgrlIG1k | L21: SEM | M21: SEM | N21: 0
A22: Aluguel de quarto - Fernando Leão | B22: 0 | C22: 0 | D22: Ao lado do Supermercado vitória, na - R. Londrina, 22 - sobrado | E22: Barro Alto | F22: Goiás | G22: BR | I22: +55 62 99800-9864 | J22: Hotel | K22: https://www.google.com/maps/search/?api=1&query=Aluguel%20de%20quarto%20-%20Fernando%20Le%C3%A3o&query_place_id=ChIJ59_p5dZNQ5MR7XmMhuVI3_o | L22: SEM | M22: SEM | N22: 0
A23: Aluguel de quartos em POA Unidade João Pessoa | B23: 0 | C23: 0 | D23: Av. João Pessoa, 817 | E23: Porto Alegre | F23: Rio Grande do Sul | G23: BR | I23: +55 51 98162-5160 | J23: Hotel | K23: https://www.google.com/maps/search/?api=1&query=Aluguel%20de%20quartos%20em%20POA%20Unidade%20Jo%C3%A3o%20Pessoa&query_place_id=ChIJgfskTkJ5GZURrRcpjy_ETz4 | L23: SEM | M23: SEM | N23: 0
A24: Aluguel Temporada Guarapari | B24: 0 | C24: 0 | D24: Av. Praiana, 1451 | E24: Guarapari | F24: Espírito Santo | G24: BR | I24: +55 67 98458-2048 | J24: Apart hotel | K24: https://www.google.com/maps/search/?api=1&query=Aluguel%20Temporada%20Guarapari&query_place_id=ChIJzXv0r8xXuAARxSLgwQyYoOU | L24: SEM | M24: SEM | N24: 0
A25: Alyssacraft1blox | B25: 0 | C25: 0 | D25: R. Manduca Nunes, 12 | E25: Porto Alegre | F25: Rio Grande do Sul | G25: BR | I25: +55 51 99206-5721 | J25: Albergue | K25: https://www.google.com/maps/search/?api=1&query=Alyssacraft1blox&query_place_id=ChIJ6bDxobuDGZUR4xuJYPh64PQ | L25: SEM | M25: SEM | N25: 0
A26: AMAZON BACK PACKERS DJALMA | B26: 0 | C26: 0 | D26: MINISHOPPING BEVELY HILLS - Av. Djalma Batista, 2339 - PISO 2 | E26: Manaus | F26: Amazonas | G26: BR | I26: +55 92 99489-7252 | J26: Albergue | K26: https://www.google.com/maps/search/?api=1&query=AMAZON%20BACK%20PACKERS%20DJALMA&query_place_id=ChIJ9fYP3acabJIRMdmozQ97WuY | L26: SEM | M26: SEM | N26: 0
A27: Amazon Geo | B27: 0 | C27: 0 | D27: Edifício Palácio do Comercio - Av. Eduardo Ribeiro, 1303 | E27: Manaus | F27: Amazonas | G27: BR | H27: http://amazongeo.com/ | J27: Hotel | K27: https://www.google.com/maps/search/?api=1&query=Amazon%20Geo&query_place_id=ChIJlTmAC30FbJIRZpdp37cSihY | L27: COM | M27: COM | N27: 0
A28: Amazonas | B28: 0 | C28: 0 | E28: Ouricuri | F28: Pernambuco | G28: BR | J28: Hotel | K28: https://www.google.com/maps/search/?api=1&query=Amazonas&query_place_id=ChIJW44NTaSNnwcRSoaCCaN5MDk | L28: SEM | M28: SEM | N28: 0
A29: American Flat Apartamento Aluguel SLZ | B29: 0 | C29: 0 | D29: American Flat - Av. dos Holandeses, S/N | E29: São Luís | F29: Maranhão | G29: BR | H29: https://www.booking.com/hotel/br/lindo-flat-apartamento-proximo-a-praia-com-vista.pt-br.html | J29: Hotel | K29: https://www.google.com/maps/search/?api=1&query=American%20Flat%20Apartamento%20Aluguel%20SLZ&query_place_id=ChIJBwP-2SKN9gcROSQhP34XTi0 | L29: COM | M29: COM | N29: 0
A30: AMILL HOSTEL | B30: 0 | C30: 0 | D30: R. Tapajós, 512 | E30: Manaus | F30: Amazonas | G30: BR | H30: https://amill-hostel.negocio.site/?utm_source=gmb&utm_medium=referral | J30: Hotel | K30: https://www.google.com/maps/search/?api=1&query=AMILL%20HOSTEL&query_place_id=ChIJ-cQB7AEFbJIRSjNKraPWdjw | L30: COM | M30: COM | N30: 0
A31: Anauê Jungle Chalés | B31: 0 | C31: 0 | D31: R. Cedrinho | E31: Manaus | F31: Amazonas | G31: BR | H31: https://anauejunglechales.com.br/ | I31: +55 92 99419-7052 | J31: Pousada | K31: https://www.google.com/maps/search/?api=1&query=Anau%C3%AA%20Jungle%20Chal%C3%A9s&query_place_id=ChIJ9RFbrLo9bJIRD_oDb1RL84U | L31: COM | M31: COM | N31: 0
A32: Anburgue noite | B32: 0 | C32: 0 | D32: R. Furtunato Silva, 224 | E32: Pedra Branca | F32: Ceará | G32: BR | J32: Albergue | K32: https://www.google.com/maps/search/?api=1&query=Anburgue%20noite&query_place_id=ChIJNegQoHafvQcRzytNO3qWNY8 | L32: SEM | M32: SEM | N32: 0
A33: anjos da fe | B33: 0 | C33: 0 | D33: R. dos Cedros, casa 12 | E33: São Luís | F33: Maranhão | G33: BR | H33: https://anjosdafe.lojavirtualnuvem.com.br/ | I33: +55 98 99220-0800 | J33: Alojamento | K33: https://www.google.com/maps/search/?api=1&query=anjos%20da%20fe&query_place_id=ChIJFWtsUxiP9gcRskX_hR0T-DQ | L33: COM | M33: COM | N33: 0
A34: Annas Hostel | B34: 0 | C34: 0 | D34: Rua Buritis, Quadra 23, Lote 11, S/n | E34: Alto Paraíso de Goiás | F34: Goiás | G34: BR | I34: +55 61 99339-0319 | J34: Albergue | K34: https://www.google.com/maps/search/?api=1&query=Annas%20Hostel&query_place_id=ChIJB3T1rHsLRZMR-UFDlA6xBOY | L34: SEM | M34: SEM | N34: 0
A35: Apart em Belém Modern | B35: 0 | C35: 0 | D35: R. Antônio Barreto, 140 - apt. 1402 | E35: Belém | F35: Pará | G35: BR | H35: https://maistelecombelem.wixsite.com/aptoembelemodern | I35: +55 91 98115-6647 | J35: Apartamento | K35: https://www.google.com/maps/search/?api=1&query=Apart%20em%20Bel%C3%A9m%20Modern&query_place_id=ChIJCdMua_WPpJIRlqDE5FPLoBo | L35: COM | M35: COM | N35: 0
A36: APART HOTEL MANAUS UN 2525 | B36: 0 | C36: 0 | D36: Av. Constantino Nery, 2525 | E36: Manaus | F36: Amazonas | G36: BR | I36: +55 92 98446-8871 | J36: Albergue | K36: https://www.google.com/maps/search/?api=1&query=APART%20HOTEL%20MANAUS%20UN%202525&query_place_id=ChIJ5d4b7QcQbJIRGWnbji1vJAk | L36: SEM | M36: SEM | N36: 0
A37: Apart Hotel Mont Blanc | B37: 0 | C37: 0 | D37: Av. Fab, 3744 | E37: Macapá | F37: Amapá | G37: BR | J37: Hotel | K37: https://www.google.com/maps/search/?api=1&query=Apart%20Hotel%20Mont%20Blanc&query_place_id=ChIJUxw1H5DhYY0RH2p4MxONNCY | L37: SEM | M37: SEM | N37: 0
A38: Apart Hotel Pioneiro | B38: 0 | C38: 0 | D38: Av. Mercúrio Norte | E38: Chapadão do Céu | F38: Goiás | G38: BR | I38: +55 64 99911-2009 | J38: Hotel | K38: https://www.google.com/maps/search/?api=1&query=Apart%20Hotel%20Pioneiro&query_place_id=ChIJq10YcPBVnZQRwzh9IOEnW_E | L38: SEM | M38: SEM | N38: 0
A39: Apartamento | B39: 0 | C39: 0 | D39: R. Costa Júnior, 1233 | E39: Jacarezinho | F39: Paraná | G39: BR | H39: https://www.facebook.com/ricar.condominios.5 | I39: +55 43 99880-6723 | J39: Hotel | K39: https://www.google.com/maps/search/?api=1&query=Apartamentos&query_place_id=ChIJ16baFVYmwJQRvQOv5Nf69BU | L39: COM | M39: COM | N39: 0
A40: Apartamento 303 | B40: 0 | C40: 0 | D40: Av. Liberdade, 3 - apartamento 303 | E40: Olinda | F40: Pernambuco | G40: BR | I40: +55 81 97900-4985 | J40: Albergue | K40: https://www.google.com/maps/search/?api=1&query=Apartamento%20303&query_place_id=ChIJ4QMhqbsiqwcRLSEf8rLV9Ms | L40: SEM | M40: SEM | N40: 0
...

Sheet Estatísticas
A1: Estatísticas Descritivas | B1: Reviews sem site | C1: Reviews com site | D1: TotalScore sem site | E1: TotalScore com site
A2: Média | B2: {=AVERAGE(_xlfn._xlws.FILTER(Dados!C:C,NOT(ISTEXT(Dados!H:H))))} -> 89.853137 | C2: {=AVERAGE(_xlfn._xlws.FILTER(Dados!C:C,ISTEXT(Dados!H:H)))} -> 778.71957 | D2: {=AVERAGE(_xlfn._xlws.FILTER(Dados!B:B,NOT(ISTEXT(Dados!H:H))))} -> 3.7049077 | E2: {=AVERAGE(_xlfn._xlws.FILTER(Dados!B:B,ISTEXT(Dados!H:H)))} -> 4.3372958
A3: Mediana | B3: {=MEDIAN(_xlfn._xlws.FILTER(Dados!C:C,NOT(ISTEXT(Dados!H:H))))} -> 25 | C3: {=MEDIAN(_xlfn._xlws.FILTER(Dados!C:C,ISTEXT(Dados!H:H)))} -> 297 | D3: {=MEDIAN(_xlfn._xlws.FILTER(Dados!B:B,NOT(ISTEXT(Dados!H:H))))} -> 4.2 | E3: {=MEDIAN(_xlfn._xlws.FILTER(Dados!B:B,ISTEXT(Dados!H:H)))} -> 4.4
A4: Moda | B4: {=_xlfn.MODE.SNGL(_xlfn._xlws.FILTER(Dados!C:C,NOT(ISTEXT(Dados!H:H))))} -> 0 | C4: {=_xlfn.MODE.SNGL(_xlfn._xlws.FILTER(Dados!C:C,ISTEXT(Dados!H:H)))} -> 0 | D4: {=_xlfn.MODE.SNGL(_xlfn._xlws.FILTER(Dados!B:B,NOT(ISTEXT(Dados!H:H))))} -> 0 | E4: {=_xlfn.MODE.SNGL(_xlfn._xlws.FILTER(Dados!B:B,ISTEXT(Dados!H:H)))} -> 4.5
A5: Desvio Padrão | B5: {=_xlfn.STDEV.S(_xlfn._xlws.FILTER(Dados!C:C,NOT(ISTEXT(Dados!H:H))))} -> 184.48875 | C5: {=_xlfn.STDEV.S(_xlfn._xlws.FILTER(Dados!C:C,ISTEXT(Dados!H:H)))} -> 1573.5366 | D5: {=_xlfn.STDEV.S(_xlfn._xlws.FILTER(Dados!B:B,NOT(ISTEXT(Dados!H:H))))} -> 1.541785 | E5: {=_xlfn.STDEV.S(_xlfn._xlws.FILTER(Dados!B:B,ISTEXT(Dados!H:H)))} -> 0.59146289
A6: Variância | B6: {=_xlfn.VAR.S(_xlfn._xlws.FILTER(Dados!C:C,NOT(ISTEXT(Dados!H:H))))} -> 34036.098 | C6: {=_xlfn.VAR.S(_xlfn._xlws.FILTER(Dados!C:C,ISTEXT(Dados!H:H)))} -> 2476017.6 | D6: {=_xlfn.VAR.S(_xlfn._xlws.FILTER(Dados!B:B,NOT(ISTEXT(Dados!H:H))))} -> 2.3771008 | E6: {=_xlfn.VAR.S(_xlfn._xlws.FILTER(Dados!B:B,ISTEXT(Dados!H:H)))} -> 0.34982835
A7: Mínimo | B7: {=MIN(_xlfn._xlws.FILTER(Dados!C:C,NOT(ISTEXT(Dados!H:H))))} -> 0 | C7: {=MIN(_xlfn._xlws.FILTER(Dados!C:C,ISTEXT(Dados!H:H)))} -> 0 | D7: {=MIN(_xlfn._xlws.FILTER(Dados!B:B,NOT(ISTEXT(Dados!H:H))))} -> 0 | E7: {=MIN(_xlfn._xlws.FILTER(Dados!B:B,ISTEXT(Dados!H:H)))} -> 0
A8: Máximo | B8: {=MAX(_xlfn._xlws.FILTER(Dados!C:C,NOT(ISTEXT(Dados!H:H))))} -> 3686 | C8: {=MAX(_xlfn._xlws.FILTER(Dados!C:C,ISTEXT(Dados!H:H)))} -> 41749 | D8: {=MAX(_xlfn._xlws.FILTER(Dados!B:B,NOT(ISTEXT(Dados!H:H))))} -> 5 | E8: {=MAX(_xlfn._xlws.FILTER(Dados!B:B,ISTEXT(Dados!H:H)))} -> 5
A9: Contagem | B9: {=COUNT(_xlfn._xlws.FILTER(Dados!C:C,NOT(ISTEXT(Dados!H:H))))} -> 5420 | C9: {=COUNT(_xlfn._xlws.FILTER(Dados!C:C,ISTEXT(Dados!H:H)))} -> 4896 | D9: {=COUNT(_xlfn._xlws.FILTER(Dados!B:B,NOT(ISTEXT(Dados!H:H))))} -> 5420 | E9: {=COUNT(_xlfn._xlws.FILTER(Dados!B:B,ISTEXT(Dados!H:H)))} -> 4896
A11: Quartis | B11: Reviews sem site | C11: Reviews com site | D11: TotalScore sem site | E11: TotalScore com site
A12: Q1 25% | B12: {=_xlfn.PERCENTILE.INC(_xlfn._xlws.FILTER(Dados!C:C,NOT(ISTEXT(Dados!H:H))),0.25)} -> 3 | C12: {=_xlfn.PERCENTILE.INC(_xlfn._xlws.FILTER(Dados!C:C,ISTEXT(Dados!H:H)),0.25)} -> 98 | D12: {=_xlfn.PERCENTILE.INC(_xlfn._xlws.FILTER(Dados!B:B,NOT(ISTEXT(Dados!H:H))),0.25)} -> 3.7 | E12: {=_xlfn.PERCENTILE.INC(_xlfn._xlws.FILTER(Dados!B:B,ISTEXT(Dados!H:H)),0.25)} -> 4.2
A13: Q2 50% | B13: {=_xlfn.PERCENTILE.INC(_xlfn._xlws.FILTER(Dados!C:C,NOT(ISTEXT(Dados!H:H))),0.5)} -> 25 | C13: {=_xlfn.PERCENTILE.INC(_xlfn._xlws.FILTER(Dados!C:C,ISTEXT(Dados!H:H)),0.5)} -> 297 | D13: {=_xlfn.PERCENTILE.INC(_xlfn._xlws.FILTER(Dados!B:B,NOT(ISTEXT(Dados!H:H))),0.5)} -> 4.2 | E13: {=_xlfn.PERCENTILE.INC(_xlfn._xlws.FILTER(Dados!B:B,ISTEXT(Dados!H:H)),0.5)} -> 4.4
A14: Q3 75% | B14: {=_xlfn.PERCENTILE.INC(_xlfn._xlws.FILTER(Dados!C:C,NOT(ISTEXT(Dados!H:H))),0.75)} -> 104 | C14: {=_xlfn.PERCENTILE.INC(_xlfn._xlws.FILTER(Dados!C:C,ISTEXT(Dados!H:H)),0.75)} -> 790 | D14: {=_xlfn.PERCENTILE.INC(_xlfn._xlws.FILTER(Dados!B:B,NOT(ISTEXT(Dados!H:H))),0.75)} -> 4.6 | E14: {=_xlfn.PERCENTILE.INC(_xlfn._xlws.FILTER(Dados!B:B,ISTEXT(Dados!H:H)),0.75)} -> 4.7
A16: Curtose e Assimetria | B16: Reviews sem site | C16: Reviews com site | D16: TotalScore sem Site | E16: TotalScore com site
A17: Curtose | B17: {=KURT(_xlfn._xlws.FILTER(Dados!C:C,NOT(ISTEXT(Dados!H:H))))} -> 76.581728 | C17: {=KURT(_xlfn._xlws.FILTER(Dados!C:C,ISTEXT(Dados!H:H)))} -> 159.52779 | D17: {=KURT(_xlfn._xlws.FILTER(Dados!B:B,NOT(ISTEXT(Dados!H:H))))} -> 1.5133051 | E17: {=KURT(_xlfn._xlws.FILTER(Dados!B:B,ISTEXT(Dados!H:H)))} -> 27.080595
A18: Assimetria | B18: {=SKEW(_xlfn._xlws.FILTER(Dados!C:C,NOT(ISTEXT(Dados!H:H))))} -> 6.525325 | C18: {=SKEW(_xlfn._xlws.FILTER(Dados!C:C,ISTEXT(Dados!H:H)))} -> 9.0225747 | D18: {=SKEW(_xlfn._xlws.FILTER(Dados!B:B,NOT(ISTEXT(Dados!H:H))))} -> -1.6979081 | E18: {=SKEW(_xlfn._xlws.FILTER(Dados!B:B,ISTEXT(Dados!H:H)))} -> -4.1999918
A20: Covariância | B20: Reviews/TotalScore sem site | C20: Reviews/TotalScore com site
A21: Valor | B21: {=_xlfn.COVARIANCE.S(_xlfn._xlws.FILTER(Dados!B:B,NOT(ISTEXT(Dados!H:H))),_xlfn._xlws.FILTER(Dados!C:C,NOT(ISTEXT(Dados!H:H))))} -> 44.335524 | C21: {=_xlfn.COVARIANCE.S(_xlfn._xlws.FILTER(Dados!B:B,ISTEXT(Dados!H:H)),_xlfn._xlws.FILTER(Dados!C:C,ISTEXT(Dados!H:H)))} -> 20.204782
A23: Amplitude | B23: Reviews sem site | C23: Reviews com site | D23: TotalScore sem site | E23: TotalScore com site
A24: Valor | B24: =B8-B7 -> 3686 | C24: =C8-C7 -> 41749 | D24: =D8-D7 -> 5 | E24: =E8-E7 -> 5
A26: Coeficiente de Variação | B26: Reviews sem site | C26: Reviews com site | D26: TotalScore sem site | E26: TotalScore com site
A27: Valor | B27: =(B5/B2) -> 2.0532255 | C27: =(C5/C2) -> 2.0206718 | D27: =(D5/D2) -> 0.41614665 | E27: =(E5/E2) -> 0.13636674

Sheet Gráficos
